<?xml version="1.0" ?>
<robot name="tway" xmlns:xacro="http://ros.org/wiki/xacro">
  <xacro:include filename="$(find tway_description)/urdf/common_properties.xacro"/>
  <!--
  <xacro:include filename="$(find tway_description)/urdf/tway_burger.gazebo.xacro"/>
  -->

  <link name="base_footprint"/>

  <joint name="base_joint" type="fixed">
    <parent link="base_footprint"/>
    <child link="base_link"/>
    <origin xyz="0.0 0.0 0.010" rpy="0 0 0"/>
  </joint>

  <link name="base_link">
    <visual>
      <origin xyz="0 0 0" rpy="0 0 0"/>
      <geometry>
        <!--
        <mesh filename="package://tway_description/meshes/bases/tway_body.stl" scale="0.001 0.001 0.001" />
        -->        
        <mesh filename="package://tway_description/meshes/bases/tway_body_nowheel.stl" scale="0.001 0.001 0.001" />
        <!--
        <mesh filename="package://tway_description/meshes/bases/tway_wheel_drive.stl" scale="0.001 0.001 0.001" />
        -->
        <!--
        <mesh filename="package://tway_description/meshes/bases/tway_wheel_steer.stl" scale="0.001 0.001 0.001" />
        -->
      </geometry>
      <material name="light_black"/>
    </visual>
  </link>

  <joint name="wheel_steer_left_joint" type="continuous">
    <parent link="base_link"/>
    <child link="wheel_steer_left_link"/>
    <origin xyz="0.40 0.00 0.20" rpy="0 0 0"/>
    <axis xyz="0 0 1"/>
  </joint>

  <link name="wheel_steer_left_link">
    <visual>
      <origin xyz="0.0 0.0 -0.225" rpy="0 0 0"/>
      <geometry>
         <mesh filename="package://tway_description/meshes/bases/tway_wheel_steer2.stl" scale="0.001 0.001 0.001" />
      </geometry>
      <!--
      <material name="dark"/>
      -->
      <material name="yellow">
        <color rgba="1 1 0 1"/>
      </material>
    </visual>
  </link>

  <joint name="wheel_driver_left_joint" type="continuous">
    <parent link="wheel_steer_left_link"/>
    <child link="wheel_driver_left_link"/>
    <origin xyz="0.00 0.00 -0.12" rpy="${-M_PI*0.5} 0 0"/>
    <axis xyz="0 0 1"/>
  </joint>

  <link name="wheel_driver_left_link">
    <visual>
      <origin xyz="0.02 -0.1092 0.0" rpy="${-M_PI*0.5} 0 0"/>
      <geometry>
         <mesh filename="package://tway_description/meshes/bases/tway_wheel_driver.stl" scale="0.001 0.001 0.001" />
      </geometry>
      <!--
      <material name="dark"/>
      -->
      <material name="red">
          <color rgba="0 0 1 1"/>
      </material>
    </visual>
  </link>

 <joint name="wheel_steer_right_joint" type="continuous">
    <parent link="base_link"/>
    <child link="wheel_steer_right_link"/>
    <origin xyz="-0.40 0.00 0.20" rpy="0 0 0"/>
    <axis xyz="0 0 1"/>
  </joint>

  <link name="wheel_steer_right_link">
    <visual>
      <origin xyz="0.0 0.0 -0.225" rpy="0 0 0"/>
      <geometry>
        <mesh filename="package://tway_description/meshes/bases/tway_wheel_steer2.stl" scale="0.001 0.001 0.001" />
      </geometry>
      <!--
      <material name="dark"/>
      -->
      <material name="yellow">
        <color rgba="1 1 0 1"/>
      </material>
    </visual>
  </link>

  <joint name="wheel_driver_right_joint" type="continuous">
    <parent link="wheel_steer_right_link"/>
    <child link="wheel_driver_right_link"/>
    <origin xyz="0.00 0.00 -0.12" rpy="${-M_PI*0.5} 0 0"/>
    <axis xyz="0 0 1"/>
  </joint>

  <link name="wheel_driver_right_link">
    <visual>
      <origin xyz="0.02 -0.1092 0.0" rpy="${-M_PI*0.5} 0 0"/>
      <geometry>
         <mesh filename="package://tway_description/meshes/bases/tway_wheel_driver.stl" scale="0.001 0.001 0.001" />
      </geometry>
      <!--
      <material name="dark"/>
      -->
      <material name="red">
          <color rgba="0 0 1 1"/>
      </material>
    </visual>
  </link>


</robot>
